[2025-05-16T13:58:22.728+0000] {taskinstance.py:1157} INFO - Dependencies all met for dep_context=non-requeueable deps ti=<TaskInstance: cdc_pipeline.check_namenode manual__2025-05-16T13:57:44.973412+00:00 [queued]>
[2025-05-16T13:58:22.844+0000] {taskinstance.py:1157} INFO - Dependencies all met for dep_context=requeueable deps ti=<TaskInstance: cdc_pipeline.check_namenode manual__2025-05-16T13:57:44.973412+00:00 [queued]>
[2025-05-16T13:58:22.849+0000] {taskinstance.py:1359} INFO - Starting attempt 1 of 4
[2025-05-16T13:58:23.130+0000] {taskinstance.py:1380} INFO - Executing <Task(BashOperator): check_namenode> on 2025-05-16 13:57:44.973412+00:00
[2025-05-16T13:58:23.223+0000] {standard_task_runner.py:57} INFO - Started process 365 to run task
[2025-05-16T13:58:23.266+0000] {standard_task_runner.py:84} INFO - Running: ['***', 'tasks', 'run', 'cdc_pipeline', 'check_namenode', 'manual__2025-05-16T13:57:44.973412+00:00', '--job-id', '9', '--raw', '--subdir', 'DAGS_FOLDER/cdc_pipeline_dag.py', '--cfg-path', '/tmp/tmpfu6zjblz']
[2025-05-16T13:58:23.370+0000] {standard_task_runner.py:85} INFO - Job 9: Subtask check_namenode
[2025-05-16T13:58:24.837+0000] {task_command.py:415} INFO - Running <TaskInstance: cdc_pipeline.check_namenode manual__2025-05-16T13:57:44.973412+00:00 [running]> on host 2325534d36fc
[2025-05-16T13:58:26.187+0000] {taskinstance.py:1660} INFO - Exporting env vars: AIRFLOW_CTX_DAG_OWNER='***' AIRFLOW_CTX_DAG_ID='cdc_pipeline' AIRFLOW_CTX_TASK_ID='check_namenode' AIRFLOW_CTX_EXECUTION_DATE='2025-05-16T13:57:44.973412+00:00' AIRFLOW_CTX_TRY_NUMBER='1' AIRFLOW_CTX_DAG_RUN_ID='manual__2025-05-16T13:57:44.973412+00:00'
[2025-05-16T13:58:26.241+0000] {subprocess.py:63} INFO - Tmp dir root location: /tmp
[2025-05-16T13:58:26.253+0000] {subprocess.py:75} INFO - Running command: ['/bin/bash', '-c', 'docker exec namenode hdfs dfsadmin -report > /dev/null || exit 1']
[2025-05-16T13:58:26.333+0000] {subprocess.py:86} INFO - Output:
[2025-05-16T13:58:40.277+0000] {subprocess.py:93} INFO - Cannot connect to the Docker daemon at unix:///var/run/docker.sock. Is the docker daemon running?
[2025-05-16T13:58:40.417+0000] {subprocess.py:97} INFO - Command exited with return code 1
[2025-05-16T13:58:40.770+0000] {taskinstance.py:1935} ERROR - Task failed with exception
Traceback (most recent call last):
  File "/home/airflow/.local/lib/python3.8/site-packages/airflow/operators/bash.py", line 210, in execute
    raise AirflowException(
airflow.exceptions.AirflowException: Bash command failed. The command returned a non-zero exit code 1.
[2025-05-16T13:58:40.844+0000] {taskinstance.py:1398} INFO - Marking task as UP_FOR_RETRY. dag_id=cdc_pipeline, task_id=check_namenode, execution_date=20250516T135744, start_date=20250516T135822, end_date=20250516T135840
[2025-05-16T13:58:41.239+0000] {standard_task_runner.py:104} ERROR - Failed to execute job 9 for task check_namenode (Bash command failed. The command returned a non-zero exit code 1.; 365)
[2025-05-16T13:58:41.514+0000] {local_task_job_runner.py:228} INFO - Task exited with return code 1
[2025-05-16T13:58:41.832+0000] {taskinstance.py:2776} INFO - 0 downstream tasks scheduled from follow-on schedule check
