[2025-05-16T14:18:38.716+0000] {taskinstance.py:1157} INFO - Dependencies all met for dep_context=non-requeueable deps ti=<TaskInstance: cdc_pipeline.check_consumer scheduled__2025-05-16T14:07:28.355202+00:00 [queued]>
[2025-05-16T14:18:38.723+0000] {taskinstance.py:1157} INFO - Dependencies all met for dep_context=requeueable deps ti=<TaskInstance: cdc_pipeline.check_consumer scheduled__2025-05-16T14:07:28.355202+00:00 [queued]>
[2025-05-16T14:18:38.724+0000] {taskinstance.py:1359} INFO - Starting attempt 2 of 4
[2025-05-16T14:18:38.734+0000] {taskinstance.py:1380} INFO - Executing <Task(BashOperator): check_consumer> on 2025-05-16 14:07:28.355202+00:00
[2025-05-16T14:18:38.738+0000] {standard_task_runner.py:57} INFO - Started process 2037 to run task
[2025-05-16T14:18:38.742+0000] {standard_task_runner.py:84} INFO - Running: ['***', 'tasks', 'run', 'cdc_pipeline', 'check_consumer', 'scheduled__2025-05-16T14:07:28.355202+00:00', '--job-id', '68', '--raw', '--subdir', 'DAGS_FOLDER/cdc_pipeline_dag.py', '--cfg-path', '/tmp/tmpvd4hksdw']
[2025-05-16T14:18:38.743+0000] {standard_task_runner.py:85} INFO - Job 68: Subtask check_consumer
[2025-05-16T14:18:38.821+0000] {task_command.py:415} INFO - Running <TaskInstance: cdc_pipeline.check_consumer scheduled__2025-05-16T14:07:28.355202+00:00 [running]> on host 2325534d36fc
[2025-05-16T14:18:38.876+0000] {taskinstance.py:1660} INFO - Exporting env vars: AIRFLOW_CTX_DAG_OWNER='***' AIRFLOW_CTX_DAG_ID='cdc_pipeline' AIRFLOW_CTX_TASK_ID='check_consumer' AIRFLOW_CTX_EXECUTION_DATE='2025-05-16T14:07:28.355202+00:00' AIRFLOW_CTX_TRY_NUMBER='2' AIRFLOW_CTX_DAG_RUN_ID='scheduled__2025-05-16T14:07:28.355202+00:00'
[2025-05-16T14:18:38.877+0000] {subprocess.py:63} INFO - Tmp dir root location: /tmp
[2025-05-16T14:18:38.878+0000] {subprocess.py:75} INFO - Running command: ['/bin/bash', '-c', 'docker ps | grep kafka-consumer > /dev/null || echo "Restarting consumer" && docker start kafka-consumer || docker run -d --name kafka-consumer --network=data_pipeline_network -e KAFKA_BOOTSTRAP_SERVERS=kafka:9092 -e HDFS_WEBHDFS_URL=http://namenode:9870/webhdfs/v1 kafka-hdfs-consumer']
[2025-05-16T14:18:38.917+0000] {subprocess.py:86} INFO - Output:
[2025-05-16T14:18:38.936+0000] {subprocess.py:93} INFO - Cannot connect to the Docker daemon at unix:///var/run/docker.sock. Is the docker daemon running?
[2025-05-16T14:18:38.938+0000] {subprocess.py:93} INFO - Restarting consumer
[2025-05-16T14:18:39.015+0000] {subprocess.py:93} INFO - Cannot connect to the Docker daemon at unix:///var/run/docker.sock. Is the docker daemon running?
[2025-05-16T14:18:39.016+0000] {subprocess.py:93} INFO - Error: failed to start containers: kafka-consumer
[2025-05-16T14:18:39.034+0000] {subprocess.py:93} INFO - docker: Cannot connect to the Docker daemon at unix:///var/run/docker.sock. Is the docker daemon running?.
[2025-05-16T14:18:39.034+0000] {subprocess.py:93} INFO - See 'docker run --help'.
[2025-05-16T14:18:39.035+0000] {subprocess.py:97} INFO - Command exited with return code 125
[2025-05-16T14:18:39.043+0000] {taskinstance.py:1935} ERROR - Task failed with exception
Traceback (most recent call last):
  File "/home/airflow/.local/lib/python3.8/site-packages/airflow/operators/bash.py", line 210, in execute
    raise AirflowException(
airflow.exceptions.AirflowException: Bash command failed. The command returned a non-zero exit code 125.
[2025-05-16T14:18:39.046+0000] {taskinstance.py:1398} INFO - Marking task as UP_FOR_RETRY. dag_id=cdc_pipeline, task_id=check_consumer, execution_date=20250516T140728, start_date=20250516T141838, end_date=20250516T141839
[2025-05-16T14:18:39.055+0000] {standard_task_runner.py:104} ERROR - Failed to execute job 68 for task check_consumer (Bash command failed. The command returned a non-zero exit code 125.; 2037)
[2025-05-16T14:18:39.076+0000] {local_task_job_runner.py:228} INFO - Task exited with return code 1
[2025-05-16T14:18:39.127+0000] {taskinstance.py:2776} INFO - 0 downstream tasks scheduled from follow-on schedule check
