[2025-05-16T14:08:47.429+0000] {taskinstance.py:1157} INFO - Dependencies all met for dep_context=non-requeueable deps ti=<TaskInstance: cdc_pipeline.check_consumer scheduled__2025-05-16T13:57:28.355202+00:00 [queued]>
[2025-05-16T14:08:47.480+0000] {taskinstance.py:1157} INFO - Dependencies all met for dep_context=requeueable deps ti=<TaskInstance: cdc_pipeline.check_consumer scheduled__2025-05-16T13:57:28.355202+00:00 [queued]>
[2025-05-16T14:08:47.481+0000] {taskinstance.py:1359} INFO - Starting attempt 2 of 4
[2025-05-16T14:08:47.554+0000] {taskinstance.py:1380} INFO - Executing <Task(BashOperator): check_consumer> on 2025-05-16 13:57:28.355202+00:00
[2025-05-16T14:08:47.571+0000] {standard_task_runner.py:57} INFO - Started process 1249 to run task
[2025-05-16T14:08:47.577+0000] {standard_task_runner.py:84} INFO - Running: ['***', 'tasks', 'run', 'cdc_pipeline', 'check_consumer', 'scheduled__2025-05-16T13:57:28.355202+00:00', '--job-id', '42', '--raw', '--subdir', 'DAGS_FOLDER/cdc_pipeline_dag.py', '--cfg-path', '/tmp/tmp9f3lg7ha']
[2025-05-16T14:08:47.581+0000] {standard_task_runner.py:85} INFO - Job 42: Subtask check_consumer
[2025-05-16T14:08:47.864+0000] {task_command.py:415} INFO - Running <TaskInstance: cdc_pipeline.check_consumer scheduled__2025-05-16T13:57:28.355202+00:00 [running]> on host 2325534d36fc
[2025-05-16T14:08:48.341+0000] {taskinstance.py:1660} INFO - Exporting env vars: AIRFLOW_CTX_DAG_OWNER='***' AIRFLOW_CTX_DAG_ID='cdc_pipeline' AIRFLOW_CTX_TASK_ID='check_consumer' AIRFLOW_CTX_EXECUTION_DATE='2025-05-16T13:57:28.355202+00:00' AIRFLOW_CTX_TRY_NUMBER='2' AIRFLOW_CTX_DAG_RUN_ID='scheduled__2025-05-16T13:57:28.355202+00:00'
[2025-05-16T14:08:48.347+0000] {subprocess.py:63} INFO - Tmp dir root location: /tmp
[2025-05-16T14:08:48.348+0000] {subprocess.py:75} INFO - Running command: ['/bin/bash', '-c', 'docker ps | grep kafka-consumer > /dev/null || echo "Restarting consumer" && docker start kafka-consumer || docker run -d --name kafka-consumer --network=data_pipeline_network -e KAFKA_BOOTSTRAP_SERVERS=kafka:9092 -e HDFS_WEBHDFS_URL=http://namenode:9870/webhdfs/v1 kafka-hdfs-consumer']
[2025-05-16T14:08:48.371+0000] {subprocess.py:86} INFO - Output:
[2025-05-16T14:08:48.552+0000] {subprocess.py:93} INFO - Cannot connect to the Docker daemon at unix:///var/run/docker.sock. Is the docker daemon running?
[2025-05-16T14:08:48.561+0000] {subprocess.py:93} INFO - Restarting consumer
[2025-05-16T14:08:48.661+0000] {subprocess.py:93} INFO - Cannot connect to the Docker daemon at unix:///var/run/docker.sock. Is the docker daemon running?
[2025-05-16T14:08:48.664+0000] {subprocess.py:93} INFO - Error: failed to start containers: kafka-consumer
[2025-05-16T14:08:48.762+0000] {subprocess.py:93} INFO - docker: Cannot connect to the Docker daemon at unix:///var/run/docker.sock. Is the docker daemon running?.
[2025-05-16T14:08:48.762+0000] {subprocess.py:93} INFO - See 'docker run --help'.
[2025-05-16T14:08:48.764+0000] {subprocess.py:97} INFO - Command exited with return code 125
[2025-05-16T14:08:48.823+0000] {taskinstance.py:1935} ERROR - Task failed with exception
Traceback (most recent call last):
  File "/home/airflow/.local/lib/python3.8/site-packages/airflow/operators/bash.py", line 210, in execute
    raise AirflowException(
airflow.exceptions.AirflowException: Bash command failed. The command returned a non-zero exit code 125.
[2025-05-16T14:08:48.826+0000] {taskinstance.py:1398} INFO - Marking task as UP_FOR_RETRY. dag_id=cdc_pipeline, task_id=check_consumer, execution_date=20250516T135728, start_date=20250516T140847, end_date=20250516T140848
[2025-05-16T14:08:48.835+0000] {standard_task_runner.py:104} ERROR - Failed to execute job 42 for task check_consumer (Bash command failed. The command returned a non-zero exit code 125.; 1249)
[2025-05-16T14:08:48.856+0000] {local_task_job_runner.py:228} INFO - Task exited with return code 1
[2025-05-16T14:08:48.876+0000] {taskinstance.py:2776} INFO - 0 downstream tasks scheduled from follow-on schedule check
