[2025-05-16T14:09:58.216+0000] {taskinstance.py:1157} INFO - Dependencies all met for dep_context=non-requeueable deps ti=<TaskInstance: cdc_pipeline.check_consumer scheduled__2025-05-16T13:57:28.355202+00:00 [queued]>
[2025-05-16T14:09:58.316+0000] {taskinstance.py:1157} INFO - Dependencies all met for dep_context=requeueable deps ti=<TaskInstance: cdc_pipeline.check_consumer scheduled__2025-05-16T13:57:28.355202+00:00 [queued]>
[2025-05-16T14:09:58.317+0000] {taskinstance.py:1359} INFO - Starting attempt 3 of 4
[2025-05-16T14:09:58.343+0000] {taskinstance.py:1380} INFO - Executing <Task(BashOperator): check_consumer> on 2025-05-16 13:57:28.355202+00:00
[2025-05-16T14:09:58.420+0000] {standard_task_runner.py:57} INFO - Started process 1359 to run task
[2025-05-16T14:09:58.431+0000] {standard_task_runner.py:84} INFO - Running: ['***', 'tasks', 'run', 'cdc_pipeline', 'check_consumer', 'scheduled__2025-05-16T13:57:28.355202+00:00', '--job-id', '46', '--raw', '--subdir', 'DAGS_FOLDER/cdc_pipeline_dag.py', '--cfg-path', '/tmp/tmpob2t8lwn']
[2025-05-16T14:09:58.439+0000] {standard_task_runner.py:85} INFO - Job 46: Subtask check_consumer
[2025-05-16T14:09:58.751+0000] {task_command.py:415} INFO - Running <TaskInstance: cdc_pipeline.check_consumer scheduled__2025-05-16T13:57:28.355202+00:00 [running]> on host 2325534d36fc
[2025-05-16T14:09:59.036+0000] {taskinstance.py:1660} INFO - Exporting env vars: AIRFLOW_CTX_DAG_OWNER='***' AIRFLOW_CTX_DAG_ID='cdc_pipeline' AIRFLOW_CTX_TASK_ID='check_consumer' AIRFLOW_CTX_EXECUTION_DATE='2025-05-16T13:57:28.355202+00:00' AIRFLOW_CTX_TRY_NUMBER='3' AIRFLOW_CTX_DAG_RUN_ID='scheduled__2025-05-16T13:57:28.355202+00:00'
[2025-05-16T14:09:59.040+0000] {subprocess.py:63} INFO - Tmp dir root location: /tmp
[2025-05-16T14:09:59.041+0000] {subprocess.py:75} INFO - Running command: ['/bin/bash', '-c', 'docker ps | grep kafka-consumer > /dev/null || echo "Restarting consumer" && docker start kafka-consumer || docker run -d --name kafka-consumer --network=data_pipeline_network -e KAFKA_BOOTSTRAP_SERVERS=kafka:9092 -e HDFS_WEBHDFS_URL=http://namenode:9870/webhdfs/v1 kafka-hdfs-consumer']
[2025-05-16T14:09:59.055+0000] {subprocess.py:86} INFO - Output:
[2025-05-16T14:09:59.137+0000] {subprocess.py:93} INFO - Cannot connect to the Docker daemon at unix:///var/run/docker.sock. Is the docker daemon running?
[2025-05-16T14:09:59.217+0000] {subprocess.py:93} INFO - Restarting consumer
[2025-05-16T14:09:59.243+0000] {subprocess.py:93} INFO - Cannot connect to the Docker daemon at unix:///var/run/docker.sock. Is the docker daemon running?
[2025-05-16T14:09:59.244+0000] {subprocess.py:93} INFO - Error: failed to start containers: kafka-consumer
[2025-05-16T14:09:59.417+0000] {subprocess.py:93} INFO - docker: Cannot connect to the Docker daemon at unix:///var/run/docker.sock. Is the docker daemon running?.
[2025-05-16T14:09:59.417+0000] {subprocess.py:93} INFO - See 'docker run --help'.
[2025-05-16T14:09:59.420+0000] {subprocess.py:97} INFO - Command exited with return code 125
[2025-05-16T14:09:59.438+0000] {taskinstance.py:1935} ERROR - Task failed with exception
Traceback (most recent call last):
  File "/home/airflow/.local/lib/python3.8/site-packages/airflow/operators/bash.py", line 210, in execute
    raise AirflowException(
airflow.exceptions.AirflowException: Bash command failed. The command returned a non-zero exit code 125.
[2025-05-16T14:09:59.442+0000] {taskinstance.py:1398} INFO - Marking task as UP_FOR_RETRY. dag_id=cdc_pipeline, task_id=check_consumer, execution_date=20250516T135728, start_date=20250516T140958, end_date=20250516T140959
[2025-05-16T14:09:59.517+0000] {standard_task_runner.py:104} ERROR - Failed to execute job 46 for task check_consumer (Bash command failed. The command returned a non-zero exit code 125.; 1359)
[2025-05-16T14:09:59.556+0000] {local_task_job_runner.py:228} INFO - Task exited with return code 1
[2025-05-16T14:09:59.716+0000] {taskinstance.py:2776} INFO - 0 downstream tasks scheduled from follow-on schedule check
