[2025-05-16T14:30:11.834+0000] {taskinstance.py:1157} INFO - Dependencies all met for dep_context=non-requeueable deps ti=<TaskInstance: cdc_pipeline.wait_for_hdfs_data manual__2025-05-16T14:27:47.907643+00:00 [queued]>
[2025-05-16T14:30:11.916+0000] {taskinstance.py:1157} INFO - Dependencies all met for dep_context=requeueable deps ti=<TaskInstance: cdc_pipeline.wait_for_hdfs_data manual__2025-05-16T14:27:47.907643+00:00 [queued]>
[2025-05-16T14:30:11.916+0000] {taskinstance.py:1359} INFO - Starting attempt 3 of 4
[2025-05-16T14:30:11.935+0000] {taskinstance.py:1380} INFO - Executing <Task(HdfsSensor): wait_for_hdfs_data> on 2025-05-16 14:27:47.907643+00:00
[2025-05-16T14:30:12.017+0000] {standard_task_runner.py:57} INFO - Started process 2664 to run task
[2025-05-16T14:30:12.024+0000] {standard_task_runner.py:84} INFO - Running: ['***', 'tasks', 'run', 'cdc_pipeline', 'wait_for_hdfs_data', 'manual__2025-05-16T14:27:47.907643+00:00', '--job-id', '97', '--raw', '--subdir', 'DAGS_FOLDER/cdc_pipeline_dag.py', '--cfg-path', '/tmp/tmpao6id6u0']
[2025-05-16T14:30:12.027+0000] {standard_task_runner.py:85} INFO - Job 97: Subtask wait_for_hdfs_data
[2025-05-16T14:30:12.225+0000] {task_command.py:415} INFO - Running <TaskInstance: cdc_pipeline.wait_for_hdfs_data manual__2025-05-16T14:27:47.907643+00:00 [running]> on host 2325534d36fc
[2025-05-16T14:30:12.522+0000] {taskinstance.py:1660} INFO - Exporting env vars: AIRFLOW_CTX_DAG_OWNER='***' AIRFLOW_CTX_DAG_ID='cdc_pipeline' AIRFLOW_CTX_TASK_ID='wait_for_hdfs_data' AIRFLOW_CTX_EXECUTION_DATE='2025-05-16T14:27:47.907643+00:00' AIRFLOW_CTX_TRY_NUMBER='3' AIRFLOW_CTX_DAG_RUN_ID='manual__2025-05-16T14:27:47.907643+00:00'
[2025-05-16T14:30:12.527+0000] {logging_mixin.py:151} WARNING - /home/***/.local/lib/python3.8/site-packages/***/providers/apache/hdfs/hooks/hdfs.py:78 RemovedInAirflow3Warning: `BaseHook.get_connections` method will be deprecated in the future.Please use `BaseHook.get_connection` instead.
[2025-05-16T14:30:12.619+0000] {taskinstance.py:1935} ERROR - Task failed with exception
Traceback (most recent call last):
  File "/home/airflow/.local/lib/python3.8/site-packages/airflow/sensors/base.py", line 257, in execute
    raise e
  File "/home/airflow/.local/lib/python3.8/site-packages/airflow/sensors/base.py", line 239, in execute
    poke_return = self.poke(context)
  File "/home/airflow/.local/lib/python3.8/site-packages/airflow/providers/apache/hdfs/sensors/hdfs.py", line 105, in poke
    sb_client = self.hook(self.hdfs_conn_id).get_conn()
  File "/home/airflow/.local/lib/python3.8/site-packages/airflow/providers/apache/hdfs/hooks/hdfs.py", line 78, in get_conn
    connections = self.get_connections(self.hdfs_conn_id)
  File "/home/airflow/.local/lib/python3.8/site-packages/airflow/hooks/base.py", line 60, in get_connections
    return [cls.get_connection(conn_id)]
  File "/home/airflow/.local/lib/python3.8/site-packages/airflow/hooks/base.py", line 72, in get_connection
    conn = Connection.get_connection_from_secrets(conn_id)
  File "/home/airflow/.local/lib/python3.8/site-packages/airflow/models/connection.py", line 477, in get_connection_from_secrets
    raise AirflowNotFoundException(f"The conn_id `{conn_id}` isn't defined")
airflow.exceptions.AirflowNotFoundException: The conn_id `hdfs_default` isn't defined
[2025-05-16T14:30:12.623+0000] {taskinstance.py:1398} INFO - Marking task as UP_FOR_RETRY. dag_id=cdc_pipeline, task_id=wait_for_hdfs_data, execution_date=20250516T142747, start_date=20250516T143011, end_date=20250516T143012
[2025-05-16T14:30:12.636+0000] {standard_task_runner.py:104} ERROR - Failed to execute job 97 for task wait_for_hdfs_data (The conn_id `hdfs_default` isn't defined; 2664)
[2025-05-16T14:30:12.715+0000] {local_task_job_runner.py:228} INFO - Task exited with return code 1
[2025-05-16T14:30:12.816+0000] {taskinstance.py:2776} INFO - 0 downstream tasks scheduled from follow-on schedule check
