[2025-05-16T14:15:38.932+0000] {taskinstance.py:1157} INFO - Dependencies all met for dep_context=non-requeueable deps ti=<TaskInstance: cdc_pipeline.check_kafka manual__2025-05-16T14:12:07.730376+00:00 [queued]>
[2025-05-16T14:15:38.944+0000] {taskinstance.py:1157} INFO - Dependencies all met for dep_context=requeueable deps ti=<TaskInstance: cdc_pipeline.check_kafka manual__2025-05-16T14:12:07.730376+00:00 [queued]>
[2025-05-16T14:15:38.944+0000] {taskinstance.py:1359} INFO - Starting attempt 4 of 4
[2025-05-16T14:15:39.036+0000] {taskinstance.py:1380} INFO - Executing <Task(BashOperator): check_kafka> on 2025-05-16 14:12:07.730376+00:00
[2025-05-16T14:15:39.048+0000] {standard_task_runner.py:57} INFO - Started process 1822 to run task
[2025-05-16T14:15:39.062+0000] {standard_task_runner.py:84} INFO - Running: ['***', 'tasks', 'run', 'cdc_pipeline', 'check_kafka', 'manual__2025-05-16T14:12:07.730376+00:00', '--job-id', '62', '--raw', '--subdir', 'DAGS_FOLDER/cdc_pipeline_dag.py', '--cfg-path', '/tmp/tmplscespd5']
[2025-05-16T14:15:39.119+0000] {standard_task_runner.py:85} INFO - Job 62: Subtask check_kafka
[2025-05-16T14:15:39.308+0000] {task_command.py:415} INFO - Running <TaskInstance: cdc_pipeline.check_kafka manual__2025-05-16T14:12:07.730376+00:00 [running]> on host 2325534d36fc
[2025-05-16T14:15:39.580+0000] {taskinstance.py:1660} INFO - Exporting env vars: AIRFLOW_CTX_DAG_OWNER='***' AIRFLOW_CTX_DAG_ID='cdc_pipeline' AIRFLOW_CTX_TASK_ID='check_kafka' AIRFLOW_CTX_EXECUTION_DATE='2025-05-16T14:12:07.730376+00:00' AIRFLOW_CTX_TRY_NUMBER='4' AIRFLOW_CTX_DAG_RUN_ID='manual__2025-05-16T14:12:07.730376+00:00'
[2025-05-16T14:15:39.600+0000] {subprocess.py:63} INFO - Tmp dir root location: /tmp
[2025-05-16T14:15:39.601+0000] {subprocess.py:75} INFO - Running command: ['/bin/bash', '-c', 'docker exec kafka kafka-topics.sh --bootstrap-server kafka:9092 --list > /dev/null || exit 1']
[2025-05-16T14:15:39.683+0000] {subprocess.py:86} INFO - Output:
[2025-05-16T14:15:39.873+0000] {subprocess.py:93} INFO - Cannot connect to the Docker daemon at unix:///var/run/docker.sock. Is the docker daemon running?
[2025-05-16T14:15:39.878+0000] {subprocess.py:97} INFO - Command exited with return code 1
[2025-05-16T14:15:39.941+0000] {taskinstance.py:1935} ERROR - Task failed with exception
Traceback (most recent call last):
  File "/home/airflow/.local/lib/python3.8/site-packages/airflow/operators/bash.py", line 210, in execute
    raise AirflowException(
airflow.exceptions.AirflowException: Bash command failed. The command returned a non-zero exit code 1.
[2025-05-16T14:15:39.953+0000] {taskinstance.py:1398} INFO - Marking task as FAILED. dag_id=cdc_pipeline, task_id=check_kafka, execution_date=20250516T141207, start_date=20250516T141538, end_date=20250516T141539
[2025-05-16T14:15:40.023+0000] {standard_task_runner.py:104} ERROR - Failed to execute job 62 for task check_kafka (Bash command failed. The command returned a non-zero exit code 1.; 1822)
[2025-05-16T14:15:40.116+0000] {local_task_job_runner.py:228} INFO - Task exited with return code 1
[2025-05-16T14:15:40.230+0000] {taskinstance.py:2776} INFO - 0 downstream tasks scheduled from follow-on schedule check
