[2025-05-16T14:01:12.762+0000] {taskinstance.py:1157} INFO - Dependencies all met for dep_context=non-requeueable deps ti=<TaskInstance: cdc_pipeline.check_namenode scheduled__2025-05-16T13:47:28.355202+00:00 [queued]>
[2025-05-16T14:01:13.026+0000] {taskinstance.py:1157} INFO - Dependencies all met for dep_context=requeueable deps ti=<TaskInstance: cdc_pipeline.check_namenode scheduled__2025-05-16T13:47:28.355202+00:00 [queued]>
[2025-05-16T14:01:13.027+0000] {taskinstance.py:1359} INFO - Starting attempt 3 of 4
[2025-05-16T14:01:13.239+0000] {taskinstance.py:1380} INFO - Executing <Task(BashOperator): check_namenode> on 2025-05-16 13:47:28.355202+00:00
[2025-05-16T14:01:13.345+0000] {standard_task_runner.py:57} INFO - Started process 637 to run task
[2025-05-16T14:01:13.424+0000] {standard_task_runner.py:84} INFO - Running: ['***', 'tasks', 'run', 'cdc_pipeline', 'check_namenode', 'scheduled__2025-05-16T13:47:28.355202+00:00', '--job-id', '22', '--raw', '--subdir', 'DAGS_FOLDER/cdc_pipeline_dag.py', '--cfg-path', '/tmp/tmpb03h_c0_']
[2025-05-16T14:01:13.431+0000] {standard_task_runner.py:85} INFO - Job 22: Subtask check_namenode
[2025-05-16T14:01:14.141+0000] {task_command.py:415} INFO - Running <TaskInstance: cdc_pipeline.check_namenode scheduled__2025-05-16T13:47:28.355202+00:00 [running]> on host 2325534d36fc
[2025-05-16T14:01:15.053+0000] {taskinstance.py:1660} INFO - Exporting env vars: AIRFLOW_CTX_DAG_OWNER='***' AIRFLOW_CTX_DAG_ID='cdc_pipeline' AIRFLOW_CTX_TASK_ID='check_namenode' AIRFLOW_CTX_EXECUTION_DATE='2025-05-16T13:47:28.355202+00:00' AIRFLOW_CTX_TRY_NUMBER='3' AIRFLOW_CTX_DAG_RUN_ID='scheduled__2025-05-16T13:47:28.355202+00:00'
[2025-05-16T14:01:15.056+0000] {subprocess.py:63} INFO - Tmp dir root location: /tmp
[2025-05-16T14:01:15.057+0000] {subprocess.py:75} INFO - Running command: ['/bin/bash', '-c', 'docker exec namenode hdfs dfsadmin -report > /dev/null || exit 1']
[2025-05-16T14:01:15.145+0000] {subprocess.py:86} INFO - Output:
[2025-05-16T14:01:16.456+0000] {subprocess.py:93} INFO - Cannot connect to the Docker daemon at unix:///var/run/docker.sock. Is the docker daemon running?
[2025-05-16T14:01:16.523+0000] {subprocess.py:97} INFO - Command exited with return code 1
[2025-05-16T14:01:16.640+0000] {taskinstance.py:1935} ERROR - Task failed with exception
Traceback (most recent call last):
  File "/home/airflow/.local/lib/python3.8/site-packages/airflow/operators/bash.py", line 210, in execute
    raise AirflowException(
airflow.exceptions.AirflowException: Bash command failed. The command returned a non-zero exit code 1.
[2025-05-16T14:01:16.735+0000] {taskinstance.py:1398} INFO - Marking task as UP_FOR_RETRY. dag_id=cdc_pipeline, task_id=check_namenode, execution_date=20250516T134728, start_date=20250516T140112, end_date=20250516T140116
[2025-05-16T14:01:17.141+0000] {standard_task_runner.py:104} ERROR - Failed to execute job 22 for task check_namenode (Bash command failed. The command returned a non-zero exit code 1.; 637)
[2025-05-16T14:01:17.416+0000] {local_task_job_runner.py:228} INFO - Task exited with return code 1
[2025-05-16T14:01:17.846+0000] {taskinstance.py:2776} INFO - 0 downstream tasks scheduled from follow-on schedule check
