[2025-05-16T14:04:32.618+0000] {taskinstance.py:1157} INFO - Dependencies all met for dep_context=non-requeueable deps ti=<TaskInstance: cdc_pipeline.check_consumer manual__2025-05-16T13:57:44.973412+00:00 [queued]>
[2025-05-16T14:04:32.629+0000] {taskinstance.py:1157} INFO - Dependencies all met for dep_context=requeueable deps ti=<TaskInstance: cdc_pipeline.check_consumer manual__2025-05-16T13:57:44.973412+00:00 [queued]>
[2025-05-16T14:04:32.630+0000] {taskinstance.py:1359} INFO - Starting attempt 2 of 4
[2025-05-16T14:04:32.717+0000] {taskinstance.py:1380} INFO - Executing <Task(BashOperator): check_consumer> on 2025-05-16 13:57:44.973412+00:00
[2025-05-16T14:04:32.726+0000] {standard_task_runner.py:57} INFO - Started process 936 to run task
[2025-05-16T14:04:32.732+0000] {standard_task_runner.py:84} INFO - Running: ['***', 'tasks', 'run', 'cdc_pipeline', 'check_consumer', 'manual__2025-05-16T13:57:44.973412+00:00', '--job-id', '32', '--raw', '--subdir', 'DAGS_FOLDER/cdc_pipeline_dag.py', '--cfg-path', '/tmp/tmp972lkw17']
[2025-05-16T14:04:32.735+0000] {standard_task_runner.py:85} INFO - Job 32: Subtask check_consumer
[2025-05-16T14:04:32.925+0000] {task_command.py:415} INFO - Running <TaskInstance: cdc_pipeline.check_consumer manual__2025-05-16T13:57:44.973412+00:00 [running]> on host 2325534d36fc
[2025-05-16T14:04:33.233+0000] {taskinstance.py:1660} INFO - Exporting env vars: AIRFLOW_CTX_DAG_OWNER='***' AIRFLOW_CTX_DAG_ID='cdc_pipeline' AIRFLOW_CTX_TASK_ID='check_consumer' AIRFLOW_CTX_EXECUTION_DATE='2025-05-16T13:57:44.973412+00:00' AIRFLOW_CTX_TRY_NUMBER='2' AIRFLOW_CTX_DAG_RUN_ID='manual__2025-05-16T13:57:44.973412+00:00'
[2025-05-16T14:04:33.236+0000] {subprocess.py:63} INFO - Tmp dir root location: /tmp
[2025-05-16T14:04:33.237+0000] {subprocess.py:75} INFO - Running command: ['/bin/bash', '-c', 'docker ps | grep kafka-consumer > /dev/null || echo "Restarting consumer" && docker start kafka-consumer || docker run -d --name kafka-consumer --network=data_pipeline_network -e KAFKA_BOOTSTRAP_SERVERS=kafka:9092 -e HDFS_WEBHDFS_URL=http://namenode:9870/webhdfs/v1 kafka-hdfs-consumer']
[2025-05-16T14:04:33.254+0000] {subprocess.py:86} INFO - Output:
[2025-05-16T14:04:33.438+0000] {subprocess.py:93} INFO - Cannot connect to the Docker daemon at unix:///var/run/docker.sock. Is the docker daemon running?
[2025-05-16T14:04:33.441+0000] {subprocess.py:93} INFO - Restarting consumer
[2025-05-16T14:04:33.546+0000] {subprocess.py:93} INFO - Cannot connect to the Docker daemon at unix:///var/run/docker.sock. Is the docker daemon running?
[2025-05-16T14:04:33.615+0000] {subprocess.py:93} INFO - Error: failed to start containers: kafka-consumer
[2025-05-16T14:04:33.734+0000] {subprocess.py:93} INFO - docker: Cannot connect to the Docker daemon at unix:///var/run/docker.sock. Is the docker daemon running?.
[2025-05-16T14:04:33.735+0000] {subprocess.py:93} INFO - See 'docker run --help'.
[2025-05-16T14:04:33.738+0000] {subprocess.py:97} INFO - Command exited with return code 125
[2025-05-16T14:04:33.834+0000] {taskinstance.py:1935} ERROR - Task failed with exception
Traceback (most recent call last):
  File "/home/airflow/.local/lib/python3.8/site-packages/airflow/operators/bash.py", line 210, in execute
    raise AirflowException(
airflow.exceptions.AirflowException: Bash command failed. The command returned a non-zero exit code 125.
[2025-05-16T14:04:33.839+0000] {taskinstance.py:1398} INFO - Marking task as UP_FOR_RETRY. dag_id=cdc_pipeline, task_id=check_consumer, execution_date=20250516T135744, start_date=20250516T140432, end_date=20250516T140433
[2025-05-16T14:04:33.857+0000] {standard_task_runner.py:104} ERROR - Failed to execute job 32 for task check_consumer (Bash command failed. The command returned a non-zero exit code 125.; 936)
[2025-05-16T14:04:33.958+0000] {local_task_job_runner.py:228} INFO - Task exited with return code 1
[2025-05-16T14:04:34.116+0000] {taskinstance.py:2776} INFO - 0 downstream tasks scheduled from follow-on schedule check
