[2025-05-16T14:40:59.033+0000] {taskinstance.py:1157} INFO - Dependencies all met for dep_context=non-requeueable deps ti=<TaskInstance: cdc_pipeline.generate_test_data manual__2025-05-16T14:40:44.810615+00:00 [queued]>
[2025-05-16T14:40:59.039+0000] {taskinstance.py:1157} INFO - Dependencies all met for dep_context=requeueable deps ti=<TaskInstance: cdc_pipeline.generate_test_data manual__2025-05-16T14:40:44.810615+00:00 [queued]>
[2025-05-16T14:40:59.040+0000] {taskinstance.py:1359} INFO - Starting attempt 1 of 4
[2025-05-16T14:40:59.049+0000] {taskinstance.py:1380} INFO - Executing <Task(PythonOperator): generate_test_data> on 2025-05-16 14:40:44.810615+00:00
[2025-05-16T14:40:59.054+0000] {standard_task_runner.py:57} INFO - Started process 3169 to run task
[2025-05-16T14:40:59.057+0000] {standard_task_runner.py:84} INFO - Running: ['***', 'tasks', 'run', 'cdc_pipeline', 'generate_test_data', 'manual__2025-05-16T14:40:44.810615+00:00', '--job-id', '116', '--raw', '--subdir', 'DAGS_FOLDER/cdc_pipeline_dag.py', '--cfg-path', '/tmp/tmppy7ux6ec']
[2025-05-16T14:40:59.059+0000] {standard_task_runner.py:85} INFO - Job 116: Subtask generate_test_data
[2025-05-16T14:40:59.145+0000] {task_command.py:415} INFO - Running <TaskInstance: cdc_pipeline.generate_test_data manual__2025-05-16T14:40:44.810615+00:00 [running]> on host 2325534d36fc
[2025-05-16T14:40:59.227+0000] {taskinstance.py:1660} INFO - Exporting env vars: AIRFLOW_CTX_DAG_OWNER='***' AIRFLOW_CTX_DAG_ID='cdc_pipeline' AIRFLOW_CTX_TASK_ID='generate_test_data' AIRFLOW_CTX_EXECUTION_DATE='2025-05-16T14:40:44.810615+00:00' AIRFLOW_CTX_TRY_NUMBER='1' AIRFLOW_CTX_DAG_RUN_ID='manual__2025-05-16T14:40:44.810615+00:00'
[2025-05-16T14:40:59.229+0000] {data_generator.py:14} INFO - Starting test data generation
[2025-05-16T14:40:59.229+0000] {data_generator.py:32} INFO - Connecting to PostgreSQL...
[2025-05-16T14:40:59.232+0000] {data_generator.py:34} INFO - Connected to PostgreSQL
[2025-05-16T14:40:59.235+0000] {data_generator.py:95} ERROR - Error generating test data: relation "customers" does not exist
LINE 1: INSERT INTO customers (first_name, last_name, email) VALUES ...
                    ^

[2025-05-16T14:40:59.235+0000] {python.py:194} INFO - Done. Returned value was: False
[2025-05-16T14:40:59.252+0000] {taskinstance.py:1398} INFO - Marking task as SUCCESS. dag_id=cdc_pipeline, task_id=generate_test_data, execution_date=20250516T144044, start_date=20250516T144059, end_date=20250516T144059
[2025-05-16T14:40:59.276+0000] {local_task_job_runner.py:228} INFO - Task exited with return code 0
[2025-05-16T14:40:59.320+0000] {taskinstance.py:2776} INFO - 1 downstream tasks scheduled from follow-on schedule check
