[2025-05-16T13:58:21.738+0000] {taskinstance.py:1157} INFO - Dependencies all met for dep_context=non-requeueable deps ti=<TaskInstance: cdc_pipeline.check_kafka scheduled__2025-05-16T13:47:28.355202+00:00 [queued]>
[2025-05-16T13:58:22.025+0000] {taskinstance.py:1157} INFO - Dependencies all met for dep_context=requeueable deps ti=<TaskInstance: cdc_pipeline.check_kafka scheduled__2025-05-16T13:47:28.355202+00:00 [queued]>
[2025-05-16T13:58:22.025+0000] {taskinstance.py:1359} INFO - Starting attempt 1 of 4
[2025-05-16T13:58:22.317+0000] {taskinstance.py:1380} INFO - Executing <Task(BashOperator): check_kafka> on 2025-05-16 13:47:28.355202+00:00
[2025-05-16T13:58:22.338+0000] {standard_task_runner.py:57} INFO - Started process 359 to run task
[2025-05-16T13:58:22.488+0000] {standard_task_runner.py:84} INFO - Running: ['***', 'tasks', 'run', 'cdc_pipeline', 'check_kafka', 'scheduled__2025-05-16T13:47:28.355202+00:00', '--job-id', '3', '--raw', '--subdir', 'DAGS_FOLDER/cdc_pipeline_dag.py', '--cfg-path', '/tmp/tmp777lnfsh']
[2025-05-16T13:58:22.552+0000] {standard_task_runner.py:85} INFO - Job 3: Subtask check_kafka
[2025-05-16T13:58:23.488+0000] {task_command.py:415} INFO - Running <TaskInstance: cdc_pipeline.check_kafka scheduled__2025-05-16T13:47:28.355202+00:00 [running]> on host 2325534d36fc
[2025-05-16T13:58:25.520+0000] {taskinstance.py:1660} INFO - Exporting env vars: AIRFLOW_CTX_DAG_OWNER='***' AIRFLOW_CTX_DAG_ID='cdc_pipeline' AIRFLOW_CTX_TASK_ID='check_kafka' AIRFLOW_CTX_EXECUTION_DATE='2025-05-16T13:47:28.355202+00:00' AIRFLOW_CTX_TRY_NUMBER='1' AIRFLOW_CTX_DAG_RUN_ID='scheduled__2025-05-16T13:47:28.355202+00:00'
[2025-05-16T13:58:25.536+0000] {subprocess.py:63} INFO - Tmp dir root location: /tmp
[2025-05-16T13:58:25.546+0000] {subprocess.py:75} INFO - Running command: ['/bin/bash', '-c', 'docker exec kafka kafka-topics.sh --bootstrap-server kafka:9092 --list > /dev/null || exit 1']
[2025-05-16T13:58:26.035+0000] {subprocess.py:86} INFO - Output:
[2025-05-16T13:58:40.317+0000] {subprocess.py:93} INFO - Cannot connect to the Docker daemon at unix:///var/run/docker.sock. Is the docker daemon running?
[2025-05-16T13:58:40.420+0000] {subprocess.py:97} INFO - Command exited with return code 1
[2025-05-16T13:58:40.767+0000] {taskinstance.py:1935} ERROR - Task failed with exception
Traceback (most recent call last):
  File "/home/airflow/.local/lib/python3.8/site-packages/airflow/operators/bash.py", line 210, in execute
    raise AirflowException(
airflow.exceptions.AirflowException: Bash command failed. The command returned a non-zero exit code 1.
[2025-05-16T13:58:40.856+0000] {taskinstance.py:1398} INFO - Marking task as UP_FOR_RETRY. dag_id=cdc_pipeline, task_id=check_kafka, execution_date=20250516T134728, start_date=20250516T135821, end_date=20250516T135840
[2025-05-16T13:58:41.349+0000] {standard_task_runner.py:104} ERROR - Failed to execute job 3 for task check_kafka (Bash command failed. The command returned a non-zero exit code 1.; 359)
