[2025-05-16T14:09:54.842+0000] {taskinstance.py:1157} INFO - Dependencies all met for dep_context=non-requeueable deps ti=<TaskInstance: cdc_pipeline.check_namenode scheduled__2025-05-16T13:57:28.355202+00:00 [queued]>
[2025-05-16T14:09:54.937+0000] {taskinstance.py:1157} INFO - Dependencies all met for dep_context=requeueable deps ti=<TaskInstance: cdc_pipeline.check_namenode scheduled__2025-05-16T13:57:28.355202+00:00 [queued]>
[2025-05-16T14:09:54.937+0000] {taskinstance.py:1359} INFO - Starting attempt 3 of 4
[2025-05-16T14:09:55.127+0000] {taskinstance.py:1380} INFO - Executing <Task(BashOperator): check_namenode> on 2025-05-16 13:57:28.355202+00:00
[2025-05-16T14:09:55.157+0000] {standard_task_runner.py:57} INFO - Started process 1334 to run task
[2025-05-16T14:09:55.239+0000] {standard_task_runner.py:84} INFO - Running: ['***', 'tasks', 'run', 'cdc_pipeline', 'check_namenode', 'scheduled__2025-05-16T13:57:28.355202+00:00', '--job-id', '44', '--raw', '--subdir', 'DAGS_FOLDER/cdc_pipeline_dag.py', '--cfg-path', '/tmp/tmpxgtnirhv']
[2025-05-16T14:09:55.324+0000] {standard_task_runner.py:85} INFO - Job 44: Subtask check_namenode
[2025-05-16T14:09:55.833+0000] {task_command.py:415} INFO - Running <TaskInstance: cdc_pipeline.check_namenode scheduled__2025-05-16T13:57:28.355202+00:00 [running]> on host 2325534d36fc
[2025-05-16T14:09:56.360+0000] {taskinstance.py:1660} INFO - Exporting env vars: AIRFLOW_CTX_DAG_OWNER='***' AIRFLOW_CTX_DAG_ID='cdc_pipeline' AIRFLOW_CTX_TASK_ID='check_namenode' AIRFLOW_CTX_EXECUTION_DATE='2025-05-16T13:57:28.355202+00:00' AIRFLOW_CTX_TRY_NUMBER='3' AIRFLOW_CTX_DAG_RUN_ID='scheduled__2025-05-16T13:57:28.355202+00:00'
[2025-05-16T14:09:56.416+0000] {subprocess.py:63} INFO - Tmp dir root location: /tmp
[2025-05-16T14:09:56.419+0000] {subprocess.py:75} INFO - Running command: ['/bin/bash', '-c', 'docker exec namenode hdfs dfsadmin -report > /dev/null || exit 1']
[2025-05-16T14:09:56.519+0000] {subprocess.py:86} INFO - Output:
[2025-05-16T14:09:56.744+0000] {subprocess.py:93} INFO - Cannot connect to the Docker daemon at unix:///var/run/docker.sock. Is the docker daemon running?
[2025-05-16T14:09:56.822+0000] {subprocess.py:97} INFO - Command exited with return code 1
[2025-05-16T14:09:56.927+0000] {taskinstance.py:1935} ERROR - Task failed with exception
Traceback (most recent call last):
  File "/home/airflow/.local/lib/python3.8/site-packages/airflow/operators/bash.py", line 210, in execute
    raise AirflowException(
airflow.exceptions.AirflowException: Bash command failed. The command returned a non-zero exit code 1.
[2025-05-16T14:09:56.939+0000] {taskinstance.py:1398} INFO - Marking task as UP_FOR_RETRY. dag_id=cdc_pipeline, task_id=check_namenode, execution_date=20250516T135728, start_date=20250516T140954, end_date=20250516T140956
[2025-05-16T14:09:57.117+0000] {standard_task_runner.py:104} ERROR - Failed to execute job 44 for task check_namenode (Bash command failed. The command returned a non-zero exit code 1.; 1334)
[2025-05-16T14:09:57.216+0000] {local_task_job_runner.py:228} INFO - Task exited with return code 1
[2025-05-16T14:09:57.428+0000] {taskinstance.py:2776} INFO - 0 downstream tasks scheduled from follow-on schedule check
