[2025-05-16T13:59:55.744+0000] {taskinstance.py:1157} INFO - Dependencies all met for dep_context=non-requeueable deps ti=<TaskInstance: cdc_pipeline.check_postgres manual__2025-05-16T13:57:44.973412+00:00 [queued]>
[2025-05-16T13:59:55.944+0000] {taskinstance.py:1157} INFO - Dependencies all met for dep_context=requeueable deps ti=<TaskInstance: cdc_pipeline.check_postgres manual__2025-05-16T13:57:44.973412+00:00 [queued]>
[2025-05-16T13:59:55.945+0000] {taskinstance.py:1359} INFO - Starting attempt 2 of 4
[2025-05-16T13:59:56.218+0000] {taskinstance.py:1380} INFO - Executing <Task(BashOperator): check_postgres> on 2025-05-16 13:57:44.973412+00:00
[2025-05-16T13:59:56.248+0000] {standard_task_runner.py:57} INFO - Started process 509 to run task
[2025-05-16T13:59:56.357+0000] {standard_task_runner.py:84} INFO - Running: ['***', 'tasks', 'run', 'cdc_pipeline', 'check_postgres', 'manual__2025-05-16T13:57:44.973412+00:00', '--job-id', '12', '--raw', '--subdir', 'DAGS_FOLDER/cdc_pipeline_dag.py', '--cfg-path', '/tmp/tmpm1_6kkhb']
[2025-05-16T13:59:56.458+0000] {standard_task_runner.py:85} INFO - Job 12: Subtask check_postgres
[2025-05-16T13:59:57.317+0000] {task_command.py:415} INFO - Running <TaskInstance: cdc_pipeline.check_postgres manual__2025-05-16T13:57:44.973412+00:00 [running]> on host 2325534d36fc
[2025-05-16T13:59:57.927+0000] {taskinstance.py:1660} INFO - Exporting env vars: AIRFLOW_CTX_DAG_OWNER='***' AIRFLOW_CTX_DAG_ID='cdc_pipeline' AIRFLOW_CTX_TASK_ID='check_postgres' AIRFLOW_CTX_EXECUTION_DATE='2025-05-16T13:57:44.973412+00:00' AIRFLOW_CTX_TRY_NUMBER='2' AIRFLOW_CTX_DAG_RUN_ID='manual__2025-05-16T13:57:44.973412+00:00'
[2025-05-16T13:59:57.936+0000] {subprocess.py:63} INFO - Tmp dir root location: /tmp
[2025-05-16T13:59:57.938+0000] {subprocess.py:75} INFO - Running command: ['/bin/bash', '-c', 'docker exec postgres pg_isready -U postgres || exit 1']
[2025-05-16T13:59:58.120+0000] {subprocess.py:86} INFO - Output:
[2025-05-16T13:59:58.629+0000] {subprocess.py:93} INFO - Cannot connect to the Docker daemon at unix:///var/run/docker.sock. Is the docker daemon running?
[2025-05-16T13:59:58.643+0000] {subprocess.py:97} INFO - Command exited with return code 1
[2025-05-16T13:59:58.832+0000] {taskinstance.py:1935} ERROR - Task failed with exception
Traceback (most recent call last):
  File "/home/airflow/.local/lib/python3.8/site-packages/airflow/operators/bash.py", line 210, in execute
    raise AirflowException(
airflow.exceptions.AirflowException: Bash command failed. The command returned a non-zero exit code 1.
[2025-05-16T13:59:58.852+0000] {taskinstance.py:1398} INFO - Marking task as UP_FOR_RETRY. dag_id=cdc_pipeline, task_id=check_postgres, execution_date=20250516T135744, start_date=20250516T135955, end_date=20250516T135958
[2025-05-16T13:59:59.149+0000] {standard_task_runner.py:104} ERROR - Failed to execute job 12 for task check_postgres (Bash command failed. The command returned a non-zero exit code 1.; 509)
[2025-05-16T13:59:59.356+0000] {local_task_job_runner.py:228} INFO - Task exited with return code 1
[2025-05-16T14:00:00.020+0000] {taskinstance.py:2776} INFO - 0 downstream tasks scheduled from follow-on schedule check
