[2025-05-16T14:02:31.621+0000] {taskinstance.py:1157} INFO - Dependencies all met for dep_context=non-requeueable deps ti=<TaskInstance: cdc_pipeline.check_postgres manual__2025-05-16T13:57:44.973412+00:00 [queued]>
[2025-05-16T14:02:31.725+0000] {taskinstance.py:1157} INFO - Dependencies all met for dep_context=requeueable deps ti=<TaskInstance: cdc_pipeline.check_postgres manual__2025-05-16T13:57:44.973412+00:00 [queued]>
[2025-05-16T14:02:31.727+0000] {taskinstance.py:1359} INFO - Starting attempt 4 of 4
[2025-05-16T14:02:31.916+0000] {taskinstance.py:1380} INFO - Executing <Task(BashOperator): check_postgres> on 2025-05-16 13:57:44.973412+00:00
[2025-05-16T14:02:31.930+0000] {standard_task_runner.py:57} INFO - Started process 772 to run task
[2025-05-16T14:02:32.021+0000] {standard_task_runner.py:84} INFO - Running: ['***', 'tasks', 'run', 'cdc_pipeline', 'check_postgres', 'manual__2025-05-16T13:57:44.973412+00:00', '--job-id', '31', '--raw', '--subdir', 'DAGS_FOLDER/cdc_pipeline_dag.py', '--cfg-path', '/tmp/tmpfb5zv4kr']
[2025-05-16T14:02:32.049+0000] {standard_task_runner.py:85} INFO - Job 31: Subtask check_postgres
[2025-05-16T14:02:32.842+0000] {task_command.py:415} INFO - Running <TaskInstance: cdc_pipeline.check_postgres manual__2025-05-16T13:57:44.973412+00:00 [running]> on host 2325534d36fc
[2025-05-16T14:02:33.939+0000] {taskinstance.py:1660} INFO - Exporting env vars: AIRFLOW_CTX_DAG_OWNER='***' AIRFLOW_CTX_DAG_ID='cdc_pipeline' AIRFLOW_CTX_TASK_ID='check_postgres' AIRFLOW_CTX_EXECUTION_DATE='2025-05-16T13:57:44.973412+00:00' AIRFLOW_CTX_TRY_NUMBER='4' AIRFLOW_CTX_DAG_RUN_ID='manual__2025-05-16T13:57:44.973412+00:00'
[2025-05-16T14:02:33.941+0000] {subprocess.py:63} INFO - Tmp dir root location: /tmp
[2025-05-16T14:02:33.947+0000] {subprocess.py:75} INFO - Running command: ['/bin/bash', '-c', 'docker exec postgres pg_isready -U postgres || exit 1']
[2025-05-16T14:02:34.136+0000] {subprocess.py:86} INFO - Output:
[2025-05-16T14:02:34.545+0000] {subprocess.py:93} INFO - Cannot connect to the Docker daemon at unix:///var/run/docker.sock. Is the docker daemon running?
[2025-05-16T14:02:34.622+0000] {subprocess.py:97} INFO - Command exited with return code 1
[2025-05-16T14:02:34.734+0000] {taskinstance.py:1935} ERROR - Task failed with exception
Traceback (most recent call last):
  File "/home/airflow/.local/lib/python3.8/site-packages/airflow/operators/bash.py", line 210, in execute
    raise AirflowException(
airflow.exceptions.AirflowException: Bash command failed. The command returned a non-zero exit code 1.
[2025-05-16T14:02:34.744+0000] {taskinstance.py:1398} INFO - Marking task as FAILED. dag_id=cdc_pipeline, task_id=check_postgres, execution_date=20250516T135744, start_date=20250516T140231, end_date=20250516T140234
[2025-05-16T14:02:34.933+0000] {standard_task_runner.py:104} ERROR - Failed to execute job 31 for task check_postgres (Bash command failed. The command returned a non-zero exit code 1.; 772)
[2025-05-16T14:02:35.116+0000] {local_task_job_runner.py:228} INFO - Task exited with return code 1
[2025-05-16T14:02:35.636+0000] {taskinstance.py:2776} INFO - 0 downstream tasks scheduled from follow-on schedule check
