[2025-05-16T14:18:43.920+0000] {taskinstance.py:1157} INFO - Dependencies all met for dep_context=non-requeueable deps ti=<TaskInstance: cdc_pipeline.check_namenode scheduled__2025-05-16T14:07:28.355202+00:00 [queued]>
[2025-05-16T14:18:43.934+0000] {taskinstance.py:1157} INFO - Dependencies all met for dep_context=requeueable deps ti=<TaskInstance: cdc_pipeline.check_namenode scheduled__2025-05-16T14:07:28.355202+00:00 [queued]>
[2025-05-16T14:18:43.935+0000] {taskinstance.py:1359} INFO - Starting attempt 2 of 4
[2025-05-16T14:18:44.026+0000] {taskinstance.py:1380} INFO - Executing <Task(BashOperator): check_namenode> on 2025-05-16 14:07:28.355202+00:00
[2025-05-16T14:18:44.038+0000] {standard_task_runner.py:57} INFO - Started process 2062 to run task
[2025-05-16T14:18:44.045+0000] {standard_task_runner.py:84} INFO - Running: ['***', 'tasks', 'run', 'cdc_pipeline', 'check_namenode', 'scheduled__2025-05-16T14:07:28.355202+00:00', '--job-id', '69', '--raw', '--subdir', 'DAGS_FOLDER/cdc_pipeline_dag.py', '--cfg-path', '/tmp/tmpk75wacqf']
[2025-05-16T14:18:44.123+0000] {standard_task_runner.py:85} INFO - Job 69: Subtask check_namenode
[2025-05-16T14:18:44.318+0000] {task_command.py:415} INFO - Running <TaskInstance: cdc_pipeline.check_namenode scheduled__2025-05-16T14:07:28.355202+00:00 [running]> on host 2325534d36fc
[2025-05-16T14:18:44.703+0000] {taskinstance.py:1660} INFO - Exporting env vars: AIRFLOW_CTX_DAG_OWNER='***' AIRFLOW_CTX_DAG_ID='cdc_pipeline' AIRFLOW_CTX_TASK_ID='check_namenode' AIRFLOW_CTX_EXECUTION_DATE='2025-05-16T14:07:28.355202+00:00' AIRFLOW_CTX_TRY_NUMBER='2' AIRFLOW_CTX_DAG_RUN_ID='scheduled__2025-05-16T14:07:28.355202+00:00'
[2025-05-16T14:18:44.724+0000] {subprocess.py:63} INFO - Tmp dir root location: /tmp
[2025-05-16T14:18:44.733+0000] {subprocess.py:75} INFO - Running command: ['/bin/bash', '-c', 'docker exec namenode hdfs dfsadmin -report > /dev/null || exit 1']
[2025-05-16T14:18:44.808+0000] {subprocess.py:86} INFO - Output:
[2025-05-16T14:18:44.939+0000] {subprocess.py:93} INFO - Cannot connect to the Docker daemon at unix:///var/run/docker.sock. Is the docker daemon running?
[2025-05-16T14:18:44.957+0000] {subprocess.py:97} INFO - Command exited with return code 1
[2025-05-16T14:18:44.991+0000] {taskinstance.py:1935} ERROR - Task failed with exception
Traceback (most recent call last):
  File "/home/airflow/.local/lib/python3.8/site-packages/airflow/operators/bash.py", line 210, in execute
    raise AirflowException(
airflow.exceptions.AirflowException: Bash command failed. The command returned a non-zero exit code 1.
[2025-05-16T14:18:45.019+0000] {taskinstance.py:1398} INFO - Marking task as UP_FOR_RETRY. dag_id=cdc_pipeline, task_id=check_namenode, execution_date=20250516T140728, start_date=20250516T141843, end_date=20250516T141845
[2025-05-16T14:18:45.040+0000] {standard_task_runner.py:104} ERROR - Failed to execute job 69 for task check_namenode (Bash command failed. The command returned a non-zero exit code 1.; 2062)
[2025-05-16T14:18:45.156+0000] {local_task_job_runner.py:228} INFO - Task exited with return code 1
[2025-05-16T14:18:45.323+0000] {taskinstance.py:2776} INFO - 0 downstream tasks scheduled from follow-on schedule check
